2022-04-13 02:28:01,697 INFO    Thread-29 :1206040 [wandb_setup.py:_flush():75] Loading settings from /home/beegass/.config/wandb/settings
2022-04-13 02:28:01,698 INFO    Thread-29 :1206040 [wandb_setup.py:_flush():75] Loading settings from wandb/settings
2022-04-13 02:28:01,698 INFO    Thread-29 :1206040 [wandb_setup.py:_flush():75] Loading settings from environment variables: {'project': 'dqn-sweeps', 'entity': 'beegass', 'root_dir': '/home/beegass/Documents/Coding/Agents/agents/dqn', 'run_id': 'o2q13lsg', 'sweep_param_path': '/home/beegass/Documents/Coding/Agents/agents/dqn/wandb/sweep-im57l1np/config-o2q13lsg.yaml', 'sweep_id': 'im57l1np'}
2022-04-13 02:28:01,698 INFO    Thread-29 :1206040 [wandb_setup.py:_flush():75] Inferring run settings from compute environment: {'program': '<python with no main file>'}
2022-04-13 02:28:01,698 INFO    Thread-29 :1206040 [wandb_init.py:_log_setup():438] Logging user logs to /home/beegass/Documents/Coding/Agents/agents/dqn/wandb/run-20220413_022801-o2q13lsg/logs/debug.log
2022-04-13 02:28:01,698 INFO    Thread-29 :1206040 [wandb_init.py:_log_setup():439] Logging internal logs to /home/beegass/Documents/Coding/Agents/agents/dqn/wandb/run-20220413_022801-o2q13lsg/logs/debug-internal.log
2022-04-13 02:28:01,698 INFO    Thread-29 :1206040 [wandb_init.py:_jupyter_setup():388] configuring jupyter hooks <wandb.sdk.wandb_init._WandbInit object at 0x7f142d03b100>
2022-04-13 02:28:01,698 INFO    Thread-29 :1206040 [wandb_init.py:init():472] calling init triggers
2022-04-13 02:28:01,698 INFO    Thread-29 :1206040 [wandb_init.py:init():475] wandb.init called with sweep_config: {'batch_size': 64, 'epsilon_decay_rate': 280, 'gamma': 0.860506998780776, 'lr': 0.5286690061670336, 'max_episodes': 1000, 'max_steps': 100000, 'p_end': 0.1, 'replay_buffer_size': 40000, 'target_freq': 487, 'weight_decay': 0.9291994821579546}
config: {'batch_size': 64, 'gamma': 0.9981, 'lr': 0.4053, 'max_episodes': 10000, 'max_steps': 100000, 'p_end': 0.1, 'replay_buffer_size': 25000, 'target_freq': 460, 'weight_decay': 0.4424, 'epsilon_decay_rate': 200}
2022-04-13 02:28:01,698 INFO    Thread-29 :1206040 [wandb_init.py:init():525] starting backend
2022-04-13 02:28:01,698 INFO    Thread-29 :1206040 [backend.py:_multiprocessing_setup():99] multiprocessing start_methods=fork,spawn,forkserver, using: spawn
2022-04-13 02:28:01,702 INFO    Thread-29 :1206040 [backend.py:ensure_launched():219] starting backend process...
2022-04-13 02:28:01,924 INFO    Thread-29 :1206040 [backend.py:ensure_launched():224] started backend process with pid: 1238931
2022-04-13 02:28:01,925 INFO    Thread-29 :1206040 [wandb_init.py:init():534] backend started and connected
2022-04-13 02:28:01,938 INFO    Thread-29 :1206040 [wandb_run.py:_config_callback():1129] config_cb None None {'batch_size': 64, 'epsilon_decay_rate': 280, 'gamma': 0.860506998780776, 'lr': 0.5286690061670336, 'max_episodes': 1000, 'max_steps': 100000, 'p_end': 0.1, 'replay_buffer_size': 40000, 'target_freq': 487, 'weight_decay': 0.9291994821579546}
2022-04-13 02:28:01,941 INFO    Thread-29 :1206040 [wandb_run.py:_label_probe_notebook():1082] probe notebook
2022-04-13 02:28:01,941 INFO    Thread-29 :1206040 [wandb_run.py:_label_probe_notebook():1092] Unable to probe notebook: 'NoneType' object has no attribute 'get'
2022-04-13 02:28:01,941 INFO    Thread-29 :1206040 [wandb_init.py:init():598] updated telemetry
2022-04-13 02:28:02,472 INFO    Thread-29 :1206040 [wandb_init.py:init():629] communicating run to backend with 30 second timeout
2022-04-13 02:28:02,876 INFO    Thread-29 :1206040 [wandb_run.py:_on_init():1922] communicating current version
2022-04-13 02:28:02,938 INFO    Thread-29 :1206040 [wandb_run.py:_on_init():1926] got version response 
2022-04-13 02:28:02,938 INFO    Thread-29 :1206040 [wandb_init.py:init():660] starting run threads in backend
2022-04-13 02:28:02,978 INFO    Thread-29 :1206040 [wandb_run.py:_console_start():1896] atexit reg
2022-04-13 02:28:02,979 INFO    Thread-29 :1206040 [wandb_run.py:_redirect():1769] redirect: SettingsConsole.WRAP
2022-04-13 02:28:02,979 INFO    Thread-29 :1206040 [wandb_run.py:_redirect():1806] Wrapping output streams.
2022-04-13 02:28:02,980 INFO    Thread-29 :1206040 [wandb_run.py:_redirect():1830] Redirects installed.
2022-04-13 02:28:02,980 INFO    Thread-29 :1206040 [wandb_init.py:init():685] run started, returning control to user process
2022-04-13 03:00:38,761 ERROR   Thread-10 :1206040 [retry.py:__call__():126] Retry attempt failed:
Traceback (most recent call last):
  File "/home/beegass/.virtualenvs/dl_1/lib/python3.8/site-packages/urllib3/connectionpool.py", line 699, in urlopen
    httplib_response = self._make_request(
  File "/home/beegass/.virtualenvs/dl_1/lib/python3.8/site-packages/urllib3/connectionpool.py", line 382, in _make_request
    self._validate_conn(conn)
  File "/home/beegass/.virtualenvs/dl_1/lib/python3.8/site-packages/urllib3/connectionpool.py", line 1010, in _validate_conn
    conn.connect()
  File "/home/beegass/.virtualenvs/dl_1/lib/python3.8/site-packages/urllib3/connection.py", line 416, in connect
    self.sock = ssl_wrap_socket(
  File "/home/beegass/.virtualenvs/dl_1/lib/python3.8/site-packages/urllib3/util/ssl_.py", line 449, in ssl_wrap_socket
    ssl_sock = _ssl_wrap_socket_impl(
  File "/home/beegass/.virtualenvs/dl_1/lib/python3.8/site-packages/urllib3/util/ssl_.py", line 493, in _ssl_wrap_socket_impl
    return ssl_context.wrap_socket(sock, server_hostname=server_hostname)
  File "/usr/lib/python3.8/ssl.py", line 500, in wrap_socket
    return self.sslsocket_class._create(
  File "/usr/lib/python3.8/ssl.py", line 1040, in _create
    self.do_handshake()
  File "/usr/lib/python3.8/ssl.py", line 1309, in do_handshake
    self._sslobj.do_handshake()
ssl.SSLEOFError: EOF occurred in violation of protocol (_ssl.c:1131)

During handling of the above exception, another exception occurred:

Traceback (most recent call last):
  File "/home/beegass/.virtualenvs/dl_1/lib/python3.8/site-packages/requests/adapters.py", line 439, in send
    resp = conn.urlopen(
  File "/home/beegass/.virtualenvs/dl_1/lib/python3.8/site-packages/urllib3/connectionpool.py", line 755, in urlopen
    retries = retries.increment(
  File "/home/beegass/.virtualenvs/dl_1/lib/python3.8/site-packages/urllib3/util/retry.py", line 574, in increment
    raise MaxRetryError(_pool, url, error or ResponseError(cause))
urllib3.exceptions.MaxRetryError: HTTPSConnectionPool(host='api.wandb.ai', port=443): Max retries exceeded with url: /graphql (Caused by SSLError(SSLEOFError(8, 'EOF occurred in violation of protocol (_ssl.c:1131)')))

During handling of the above exception, another exception occurred:

Traceback (most recent call last):
  File "/home/beegass/.virtualenvs/dl_1/lib/python3.8/site-packages/wandb/sdk/lib/retry.py", line 102, in __call__
    result = self._call_fn(*args, **kwargs)
  File "/home/beegass/.virtualenvs/dl_1/lib/python3.8/site-packages/wandb/sdk/internal/internal_api.py", line 141, in execute
    return self.client.execute(*args, **kwargs)
  File "/home/beegass/.virtualenvs/dl_1/lib/python3.8/site-packages/wandb/vendor/gql-0.2.0/wandb_gql/client.py", line 52, in execute
    result = self._get_result(document, *args, **kwargs)
  File "/home/beegass/.virtualenvs/dl_1/lib/python3.8/site-packages/wandb/vendor/gql-0.2.0/wandb_gql/client.py", line 60, in _get_result
    return self.transport.execute(document, *args, **kwargs)
  File "/home/beegass/.virtualenvs/dl_1/lib/python3.8/site-packages/wandb/vendor/gql-0.2.0/wandb_gql/transport/requests.py", line 38, in execute
    request = requests.post(self.url, **post_args)
  File "/home/beegass/.virtualenvs/dl_1/lib/python3.8/site-packages/requests/api.py", line 117, in post
    return request('post', url, data=data, json=json, **kwargs)
  File "/home/beegass/.virtualenvs/dl_1/lib/python3.8/site-packages/requests/api.py", line 61, in request
    return session.request(method=method, url=url, **kwargs)
  File "/home/beegass/.virtualenvs/dl_1/lib/python3.8/site-packages/requests/sessions.py", line 542, in request
    resp = self.send(prep, **send_kwargs)
  File "/home/beegass/.virtualenvs/dl_1/lib/python3.8/site-packages/requests/sessions.py", line 655, in send
    r = adapter.send(request, **kwargs)
  File "/home/beegass/.virtualenvs/dl_1/lib/python3.8/site-packages/requests/adapters.py", line 514, in send
    raise SSLError(e, request=request)
requests.exceptions.SSLError: HTTPSConnectionPool(host='api.wandb.ai', port=443): Max retries exceeded with url: /graphql (Caused by SSLError(SSLEOFError(8, 'EOF occurred in violation of protocol (_ssl.c:1131)')))
2022-04-13 03:10:52,851 ERROR   Thread-10 :1206040 [retry.py:__call__():126] Retry attempt failed:
Traceback (most recent call last):
  File "/home/beegass/.virtualenvs/dl_1/lib/python3.8/site-packages/urllib3/connectionpool.py", line 699, in urlopen
    httplib_response = self._make_request(
  File "/home/beegass/.virtualenvs/dl_1/lib/python3.8/site-packages/urllib3/connectionpool.py", line 382, in _make_request
    self._validate_conn(conn)
  File "/home/beegass/.virtualenvs/dl_1/lib/python3.8/site-packages/urllib3/connectionpool.py", line 1010, in _validate_conn
    conn.connect()
  File "/home/beegass/.virtualenvs/dl_1/lib/python3.8/site-packages/urllib3/connection.py", line 416, in connect
    self.sock = ssl_wrap_socket(
  File "/home/beegass/.virtualenvs/dl_1/lib/python3.8/site-packages/urllib3/util/ssl_.py", line 449, in ssl_wrap_socket
    ssl_sock = _ssl_wrap_socket_impl(
  File "/home/beegass/.virtualenvs/dl_1/lib/python3.8/site-packages/urllib3/util/ssl_.py", line 493, in _ssl_wrap_socket_impl
    return ssl_context.wrap_socket(sock, server_hostname=server_hostname)
  File "/usr/lib/python3.8/ssl.py", line 500, in wrap_socket
    return self.sslsocket_class._create(
  File "/usr/lib/python3.8/ssl.py", line 1040, in _create
    self.do_handshake()
  File "/usr/lib/python3.8/ssl.py", line 1309, in do_handshake
    self._sslobj.do_handshake()
ssl.SSLEOFError: EOF occurred in violation of protocol (_ssl.c:1131)

During handling of the above exception, another exception occurred:

Traceback (most recent call last):
  File "/home/beegass/.virtualenvs/dl_1/lib/python3.8/site-packages/requests/adapters.py", line 439, in send
    resp = conn.urlopen(
  File "/home/beegass/.virtualenvs/dl_1/lib/python3.8/site-packages/urllib3/connectionpool.py", line 755, in urlopen
    retries = retries.increment(
  File "/home/beegass/.virtualenvs/dl_1/lib/python3.8/site-packages/urllib3/util/retry.py", line 574, in increment
    raise MaxRetryError(_pool, url, error or ResponseError(cause))
urllib3.exceptions.MaxRetryError: HTTPSConnectionPool(host='api.wandb.ai', port=443): Max retries exceeded with url: /graphql (Caused by SSLError(SSLEOFError(8, 'EOF occurred in violation of protocol (_ssl.c:1131)')))

During handling of the above exception, another exception occurred:

Traceback (most recent call last):
  File "/home/beegass/.virtualenvs/dl_1/lib/python3.8/site-packages/wandb/sdk/lib/retry.py", line 102, in __call__
    result = self._call_fn(*args, **kwargs)
  File "/home/beegass/.virtualenvs/dl_1/lib/python3.8/site-packages/wandb/sdk/internal/internal_api.py", line 141, in execute
    return self.client.execute(*args, **kwargs)
  File "/home/beegass/.virtualenvs/dl_1/lib/python3.8/site-packages/wandb/vendor/gql-0.2.0/wandb_gql/client.py", line 52, in execute
    result = self._get_result(document, *args, **kwargs)
  File "/home/beegass/.virtualenvs/dl_1/lib/python3.8/site-packages/wandb/vendor/gql-0.2.0/wandb_gql/client.py", line 60, in _get_result
    return self.transport.execute(document, *args, **kwargs)
  File "/home/beegass/.virtualenvs/dl_1/lib/python3.8/site-packages/wandb/vendor/gql-0.2.0/wandb_gql/transport/requests.py", line 38, in execute
    request = requests.post(self.url, **post_args)
  File "/home/beegass/.virtualenvs/dl_1/lib/python3.8/site-packages/requests/api.py", line 117, in post
    return request('post', url, data=data, json=json, **kwargs)
  File "/home/beegass/.virtualenvs/dl_1/lib/python3.8/site-packages/requests/api.py", line 61, in request
    return session.request(method=method, url=url, **kwargs)
  File "/home/beegass/.virtualenvs/dl_1/lib/python3.8/site-packages/requests/sessions.py", line 542, in request
    resp = self.send(prep, **send_kwargs)
  File "/home/beegass/.virtualenvs/dl_1/lib/python3.8/site-packages/requests/sessions.py", line 655, in send
    r = adapter.send(request, **kwargs)
  File "/home/beegass/.virtualenvs/dl_1/lib/python3.8/site-packages/requests/adapters.py", line 514, in send
    raise SSLError(e, request=request)
requests.exceptions.SSLError: HTTPSConnectionPool(host='api.wandb.ai', port=443): Max retries exceeded with url: /graphql (Caused by SSLError(SSLEOFError(8, 'EOF occurred in violation of protocol (_ssl.c:1131)')))
2022-04-13 03:17:36,205 ERROR   Thread-10 :1206040 [retry.py:__call__():126] Retry attempt failed:
Traceback (most recent call last):
  File "/home/beegass/.virtualenvs/dl_1/lib/python3.8/site-packages/urllib3/connectionpool.py", line 699, in urlopen
    httplib_response = self._make_request(
  File "/home/beegass/.virtualenvs/dl_1/lib/python3.8/site-packages/urllib3/connectionpool.py", line 382, in _make_request
    self._validate_conn(conn)
  File "/home/beegass/.virtualenvs/dl_1/lib/python3.8/site-packages/urllib3/connectionpool.py", line 1010, in _validate_conn
    conn.connect()
  File "/home/beegass/.virtualenvs/dl_1/lib/python3.8/site-packages/urllib3/connection.py", line 416, in connect
    self.sock = ssl_wrap_socket(
  File "/home/beegass/.virtualenvs/dl_1/lib/python3.8/site-packages/urllib3/util/ssl_.py", line 449, in ssl_wrap_socket
    ssl_sock = _ssl_wrap_socket_impl(
  File "/home/beegass/.virtualenvs/dl_1/lib/python3.8/site-packages/urllib3/util/ssl_.py", line 493, in _ssl_wrap_socket_impl
    return ssl_context.wrap_socket(sock, server_hostname=server_hostname)
  File "/usr/lib/python3.8/ssl.py", line 500, in wrap_socket
    return self.sslsocket_class._create(
  File "/usr/lib/python3.8/ssl.py", line 1040, in _create
    self.do_handshake()
  File "/usr/lib/python3.8/ssl.py", line 1309, in do_handshake
    self._sslobj.do_handshake()
ssl.SSLEOFError: EOF occurred in violation of protocol (_ssl.c:1131)

During handling of the above exception, another exception occurred:

Traceback (most recent call last):
  File "/home/beegass/.virtualenvs/dl_1/lib/python3.8/site-packages/requests/adapters.py", line 439, in send
    resp = conn.urlopen(
  File "/home/beegass/.virtualenvs/dl_1/lib/python3.8/site-packages/urllib3/connectionpool.py", line 755, in urlopen
    retries = retries.increment(
  File "/home/beegass/.virtualenvs/dl_1/lib/python3.8/site-packages/urllib3/util/retry.py", line 574, in increment
    raise MaxRetryError(_pool, url, error or ResponseError(cause))
urllib3.exceptions.MaxRetryError: HTTPSConnectionPool(host='api.wandb.ai', port=443): Max retries exceeded with url: /graphql (Caused by SSLError(SSLEOFError(8, 'EOF occurred in violation of protocol (_ssl.c:1131)')))

During handling of the above exception, another exception occurred:

Traceback (most recent call last):
  File "/home/beegass/.virtualenvs/dl_1/lib/python3.8/site-packages/wandb/sdk/lib/retry.py", line 102, in __call__
    result = self._call_fn(*args, **kwargs)
  File "/home/beegass/.virtualenvs/dl_1/lib/python3.8/site-packages/wandb/sdk/internal/internal_api.py", line 141, in execute
    return self.client.execute(*args, **kwargs)
  File "/home/beegass/.virtualenvs/dl_1/lib/python3.8/site-packages/wandb/vendor/gql-0.2.0/wandb_gql/client.py", line 52, in execute
    result = self._get_result(document, *args, **kwargs)
  File "/home/beegass/.virtualenvs/dl_1/lib/python3.8/site-packages/wandb/vendor/gql-0.2.0/wandb_gql/client.py", line 60, in _get_result
    return self.transport.execute(document, *args, **kwargs)
  File "/home/beegass/.virtualenvs/dl_1/lib/python3.8/site-packages/wandb/vendor/gql-0.2.0/wandb_gql/transport/requests.py", line 38, in execute
    request = requests.post(self.url, **post_args)
  File "/home/beegass/.virtualenvs/dl_1/lib/python3.8/site-packages/requests/api.py", line 117, in post
    return request('post', url, data=data, json=json, **kwargs)
  File "/home/beegass/.virtualenvs/dl_1/lib/python3.8/site-packages/requests/api.py", line 61, in request
    return session.request(method=method, url=url, **kwargs)
  File "/home/beegass/.virtualenvs/dl_1/lib/python3.8/site-packages/requests/sessions.py", line 542, in request
    resp = self.send(prep, **send_kwargs)
  File "/home/beegass/.virtualenvs/dl_1/lib/python3.8/site-packages/requests/sessions.py", line 655, in send
    r = adapter.send(request, **kwargs)
  File "/home/beegass/.virtualenvs/dl_1/lib/python3.8/site-packages/requests/adapters.py", line 514, in send
    raise SSLError(e, request=request)
requests.exceptions.SSLError: HTTPSConnectionPool(host='api.wandb.ai', port=443): Max retries exceeded with url: /graphql (Caused by SSLError(SSLEOFError(8, 'EOF occurred in violation of protocol (_ssl.c:1131)')))
2022-04-13 03:38:25,275 ERROR   Thread-10 :1206040 [retry.py:__call__():126] Retry attempt failed:
Traceback (most recent call last):
  File "/home/beegass/.virtualenvs/dl_1/lib/python3.8/site-packages/urllib3/connection.py", line 174, in _new_conn
    conn = connection.create_connection(
  File "/home/beegass/.virtualenvs/dl_1/lib/python3.8/site-packages/urllib3/util/connection.py", line 73, in create_connection
    for res in socket.getaddrinfo(host, port, family, socket.SOCK_STREAM):
  File "/usr/lib/python3.8/socket.py", line 918, in getaddrinfo
    for res in _socket.getaddrinfo(host, port, family, type, proto, flags):
socket.gaierror: [Errno -3] Temporary failure in name resolution

During handling of the above exception, another exception occurred:

Traceback (most recent call last):
  File "/home/beegass/.virtualenvs/dl_1/lib/python3.8/site-packages/urllib3/connectionpool.py", line 699, in urlopen
    httplib_response = self._make_request(
  File "/home/beegass/.virtualenvs/dl_1/lib/python3.8/site-packages/urllib3/connectionpool.py", line 382, in _make_request
    self._validate_conn(conn)
  File "/home/beegass/.virtualenvs/dl_1/lib/python3.8/site-packages/urllib3/connectionpool.py", line 1010, in _validate_conn
    conn.connect()
  File "/home/beegass/.virtualenvs/dl_1/lib/python3.8/site-packages/urllib3/connection.py", line 358, in connect
    conn = self._new_conn()
  File "/home/beegass/.virtualenvs/dl_1/lib/python3.8/site-packages/urllib3/connection.py", line 186, in _new_conn
    raise NewConnectionError(
urllib3.exceptions.NewConnectionError: <urllib3.connection.HTTPSConnection object at 0x7f142cff9190>: Failed to establish a new connection: [Errno -3] Temporary failure in name resolution

During handling of the above exception, another exception occurred:

Traceback (most recent call last):
  File "/home/beegass/.virtualenvs/dl_1/lib/python3.8/site-packages/requests/adapters.py", line 439, in send
    resp = conn.urlopen(
  File "/home/beegass/.virtualenvs/dl_1/lib/python3.8/site-packages/urllib3/connectionpool.py", line 755, in urlopen
    retries = retries.increment(
  File "/home/beegass/.virtualenvs/dl_1/lib/python3.8/site-packages/urllib3/util/retry.py", line 574, in increment
    raise MaxRetryError(_pool, url, error or ResponseError(cause))
urllib3.exceptions.MaxRetryError: HTTPSConnectionPool(host='api.wandb.ai', port=443): Max retries exceeded with url: /graphql (Caused by NewConnectionError('<urllib3.connection.HTTPSConnection object at 0x7f142cff9190>: Failed to establish a new connection: [Errno -3] Temporary failure in name resolution'))

During handling of the above exception, another exception occurred:

Traceback (most recent call last):
  File "/home/beegass/.virtualenvs/dl_1/lib/python3.8/site-packages/wandb/sdk/lib/retry.py", line 102, in __call__
    result = self._call_fn(*args, **kwargs)
  File "/home/beegass/.virtualenvs/dl_1/lib/python3.8/site-packages/wandb/sdk/internal/internal_api.py", line 141, in execute
    return self.client.execute(*args, **kwargs)
  File "/home/beegass/.virtualenvs/dl_1/lib/python3.8/site-packages/wandb/vendor/gql-0.2.0/wandb_gql/client.py", line 52, in execute
    result = self._get_result(document, *args, **kwargs)
  File "/home/beegass/.virtualenvs/dl_1/lib/python3.8/site-packages/wandb/vendor/gql-0.2.0/wandb_gql/client.py", line 60, in _get_result
    return self.transport.execute(document, *args, **kwargs)
  File "/home/beegass/.virtualenvs/dl_1/lib/python3.8/site-packages/wandb/vendor/gql-0.2.0/wandb_gql/transport/requests.py", line 38, in execute
    request = requests.post(self.url, **post_args)
  File "/home/beegass/.virtualenvs/dl_1/lib/python3.8/site-packages/requests/api.py", line 117, in post
    return request('post', url, data=data, json=json, **kwargs)
  File "/home/beegass/.virtualenvs/dl_1/lib/python3.8/site-packages/requests/api.py", line 61, in request
    return session.request(method=method, url=url, **kwargs)
  File "/home/beegass/.virtualenvs/dl_1/lib/python3.8/site-packages/requests/sessions.py", line 542, in request
    resp = self.send(prep, **send_kwargs)
  File "/home/beegass/.virtualenvs/dl_1/lib/python3.8/site-packages/requests/sessions.py", line 655, in send
    r = adapter.send(request, **kwargs)
  File "/home/beegass/.virtualenvs/dl_1/lib/python3.8/site-packages/requests/adapters.py", line 516, in send
    raise ConnectionError(e, request=request)
requests.exceptions.ConnectionError: HTTPSConnectionPool(host='api.wandb.ai', port=443): Max retries exceeded with url: /graphql (Caused by NewConnectionError('<urllib3.connection.HTTPSConnection object at 0x7f142cff9190>: Failed to establish a new connection: [Errno -3] Temporary failure in name resolution'))
2022-04-13 04:00:34,670 ERROR   Thread-10 :1206040 [retry.py:__call__():126] Retry attempt failed:
Traceback (most recent call last):
  File "/home/beegass/.virtualenvs/dl_1/lib/python3.8/site-packages/urllib3/connectionpool.py", line 699, in urlopen
    httplib_response = self._make_request(
  File "/home/beegass/.virtualenvs/dl_1/lib/python3.8/site-packages/urllib3/connectionpool.py", line 382, in _make_request
    self._validate_conn(conn)
  File "/home/beegass/.virtualenvs/dl_1/lib/python3.8/site-packages/urllib3/connectionpool.py", line 1010, in _validate_conn
    conn.connect()
  File "/home/beegass/.virtualenvs/dl_1/lib/python3.8/site-packages/urllib3/connection.py", line 416, in connect
    self.sock = ssl_wrap_socket(
  File "/home/beegass/.virtualenvs/dl_1/lib/python3.8/site-packages/urllib3/util/ssl_.py", line 449, in ssl_wrap_socket
    ssl_sock = _ssl_wrap_socket_impl(
  File "/home/beegass/.virtualenvs/dl_1/lib/python3.8/site-packages/urllib3/util/ssl_.py", line 493, in _ssl_wrap_socket_impl
    return ssl_context.wrap_socket(sock, server_hostname=server_hostname)
  File "/usr/lib/python3.8/ssl.py", line 500, in wrap_socket
    return self.sslsocket_class._create(
  File "/usr/lib/python3.8/ssl.py", line 1040, in _create
    self.do_handshake()
  File "/usr/lib/python3.8/ssl.py", line 1309, in do_handshake
    self._sslobj.do_handshake()
ssl.SSLEOFError: EOF occurred in violation of protocol (_ssl.c:1131)

During handling of the above exception, another exception occurred:

Traceback (most recent call last):
  File "/home/beegass/.virtualenvs/dl_1/lib/python3.8/site-packages/requests/adapters.py", line 439, in send
    resp = conn.urlopen(
  File "/home/beegass/.virtualenvs/dl_1/lib/python3.8/site-packages/urllib3/connectionpool.py", line 755, in urlopen
    retries = retries.increment(
  File "/home/beegass/.virtualenvs/dl_1/lib/python3.8/site-packages/urllib3/util/retry.py", line 574, in increment
    raise MaxRetryError(_pool, url, error or ResponseError(cause))
urllib3.exceptions.MaxRetryError: HTTPSConnectionPool(host='api.wandb.ai', port=443): Max retries exceeded with url: /graphql (Caused by SSLError(SSLEOFError(8, 'EOF occurred in violation of protocol (_ssl.c:1131)')))

During handling of the above exception, another exception occurred:

Traceback (most recent call last):
  File "/home/beegass/.virtualenvs/dl_1/lib/python3.8/site-packages/wandb/sdk/lib/retry.py", line 102, in __call__
    result = self._call_fn(*args, **kwargs)
  File "/home/beegass/.virtualenvs/dl_1/lib/python3.8/site-packages/wandb/sdk/internal/internal_api.py", line 141, in execute
    return self.client.execute(*args, **kwargs)
  File "/home/beegass/.virtualenvs/dl_1/lib/python3.8/site-packages/wandb/vendor/gql-0.2.0/wandb_gql/client.py", line 52, in execute
    result = self._get_result(document, *args, **kwargs)
  File "/home/beegass/.virtualenvs/dl_1/lib/python3.8/site-packages/wandb/vendor/gql-0.2.0/wandb_gql/client.py", line 60, in _get_result
    return self.transport.execute(document, *args, **kwargs)
  File "/home/beegass/.virtualenvs/dl_1/lib/python3.8/site-packages/wandb/vendor/gql-0.2.0/wandb_gql/transport/requests.py", line 38, in execute
    request = requests.post(self.url, **post_args)
  File "/home/beegass/.virtualenvs/dl_1/lib/python3.8/site-packages/requests/api.py", line 117, in post
    return request('post', url, data=data, json=json, **kwargs)
  File "/home/beegass/.virtualenvs/dl_1/lib/python3.8/site-packages/requests/api.py", line 61, in request
    return session.request(method=method, url=url, **kwargs)
  File "/home/beegass/.virtualenvs/dl_1/lib/python3.8/site-packages/requests/sessions.py", line 542, in request
    resp = self.send(prep, **send_kwargs)
  File "/home/beegass/.virtualenvs/dl_1/lib/python3.8/site-packages/requests/sessions.py", line 655, in send
    r = adapter.send(request, **kwargs)
  File "/home/beegass/.virtualenvs/dl_1/lib/python3.8/site-packages/requests/adapters.py", line 514, in send
    raise SSLError(e, request=request)
requests.exceptions.SSLError: HTTPSConnectionPool(host='api.wandb.ai', port=443): Max retries exceeded with url: /graphql (Caused by SSLError(SSLEOFError(8, 'EOF occurred in violation of protocol (_ssl.c:1131)')))
